Traceback (most recent call last):
  File "C:\Users\jqbon\anaconda3\Lib\site-packages\jupyter_cache\executors\utils.py", line 58, in single_nb_execution
    executenb(
  File "C:\Users\jqbon\anaconda3\Lib\site-packages\nbclient\client.py", line 1305, in execute
    return NotebookClient(nb=nb, resources=resources, km=km, **kwargs).execute()
           ^^^^^^^^^^^^^^^^^^^^^^^^^^^^^^^^^^^^^^^^^^^^^^^^^^^^^^^^^^^^^^^^^^^^^
  File "C:\Users\jqbon\anaconda3\Lib\site-packages\jupyter_core\utils\__init__.py", line 165, in wrapped
    return loop.run_until_complete(inner)
           ^^^^^^^^^^^^^^^^^^^^^^^^^^^^^^
  File "C:\Users\jqbon\anaconda3\Lib\asyncio\base_events.py", line 687, in run_until_complete
    return future.result()
           ^^^^^^^^^^^^^^^
  File "C:\Users\jqbon\anaconda3\Lib\site-packages\nbclient\client.py", line 705, in async_execute
    await self.async_execute_cell(
  File "C:\Users\jqbon\anaconda3\Lib\site-packages\nbclient\client.py", line 1058, in async_execute_cell
    await self._check_raise_for_error(cell, cell_index, exec_reply)
  File "C:\Users\jqbon\anaconda3\Lib\site-packages\nbclient\client.py", line 914, in _check_raise_for_error
    raise CellExecutionError.from_cell_and_msg(cell, exec_reply_content)
nbclient.exceptions.CellExecutionError: An error occurred while executing the following cell:
------------------
######################################################################################
# Load startup data from .csv file                                                   #
######################################################################################

NS0 = 10
DATA1, HEADER1 = readdlm("FLOW_TRANSIENT_1.csv",  ',', Any, '\n', header = true)
DATA2, HEADER2 = readdlm("FLOW_TRANSIENT_2.csv",  ',', Any, '\n', header = true)
DATA3, HEADER3 = readdlm("FLOW_TRANSIENT_3.csv",  ',', Any, '\n', header = true)
DATA4, HEADER4 = readdlm("FLOW_TRANSIENT_4.csv",  ',', Any, '\n', header = true)
DATA5, HEADER5 = readdlm("FLOW_TRANSIENT_5.csv",  ',', Any, '\n', header = true)


# Ensure that numbers are formatted as Floating Point Decimals (64bit)
DATA1 = Float64.(DATA1); DATA2 = Float64.(DATA2); DATA3 = Float64.(DATA3); DATA4 = Float64.(DATA4); DATA5 = Float64.(DATA5)

# Assign meaningful labels to various experimental quantities from each data set.
t1   = DATA1[:, 1]; FA1 = DATA1[:, 2]; FB1 = DATA1[:, 3]; FC1 = DATA1[:, 4]; FP1 = DATA1[:, 5]; XA1 = DATA1[:, 6]; θA1 = DATA1[:, 7]; θB1 = DATA1[:, 8]; θC1 = DATA1[:, 9]; θP1 = DATA1[:, 10]; θV1 = DATA1[:, 11];
t2   = DATA2[:, 1]; FA2 = DATA2[:, 2]; FB2 = DATA2[:, 3]; FC2 = DATA2[:, 4]; FP2 = DATA2[:, 5]; XA2 = DATA2[:, 6]; θA2 = DATA2[:, 7]; θB2 = DATA2[:, 8]; θC2 = DATA2[:, 9]; θP2 = DATA2[:, 10]; θV2 = DATA2[:, 11]; 
t3   = DATA3[:, 1]; FA3 = DATA3[:, 2]; FB3 = DATA3[:, 3]; FC3 = DATA3[:, 4]; FP3 = DATA3[:, 5]; XA3 = DATA3[:, 6]; θA3 = DATA3[:, 7]; θB3 = DATA3[:, 8]; θC3 = DATA3[:, 9]; θP3 = DATA3[:, 10]; θV3 = DATA3[:, 11];
t4   = DATA4[:, 1]; FA4 = DATA4[:, 2]; FB4 = DATA4[:, 3]; FC4 = DATA4[:, 4]; FP4 = DATA4[:, 5]; XA4 = DATA4[:, 6]; θA4 = DATA4[:, 7]; θB4 = DATA4[:, 8]; θC4 = DATA4[:, 9]; θP4 = DATA4[:, 10]; θV4 = DATA4[:, 11];
t5   = DATA5[:, 1]; FA5 = DATA5[:, 2]; FB5 = DATA5[:, 3]; FC5 = DATA5[:, 4]; FP5 = DATA5[:, 5]; XA5 = DATA5[:, 6]; θA5 = DATA5[:, 7]; θB5 = DATA5[:, 8]; θC5 = DATA5[:, 9]; θP5 = DATA5[:, 10]; θV5 = DATA5[:, 11];
------------------


ArgumentError: Cannot open 'FLOW_TRANSIENT_1.csv': not a file

Stacktrace:
 [1] readdlm_auto(input::String, dlm::Char, T::Type, eol::Char, auto::Bool; opts::@Kwargs{header::Bool})
   @ DelimitedFiles C:\Users\jqbon\.julia\packages\DelimitedFiles\aGcsu\src\DelimitedFiles.jl:234
 [2] readdlm_auto
   @ C:\Users\jqbon\.julia\packages\DelimitedFiles\aGcsu\src\DelimitedFiles.jl:233 [inlined]
 [3] #readdlm#6
   @ C:\Users\jqbon\.julia\packages\DelimitedFiles\aGcsu\src\DelimitedFiles.jl:226 [inlined]
 [4] top-level scope
   @ In[3]:6

