Traceback (most recent call last):
  File "C:\Users\jqbon\anaconda3\Lib\site-packages\jupyter_cache\executors\utils.py", line 58, in single_nb_execution
    executenb(
  File "C:\Users\jqbon\anaconda3\Lib\site-packages\nbclient\client.py", line 1305, in execute
    return NotebookClient(nb=nb, resources=resources, km=km, **kwargs).execute()
           ^^^^^^^^^^^^^^^^^^^^^^^^^^^^^^^^^^^^^^^^^^^^^^^^^^^^^^^^^^^^^^^^^^^^^
  File "C:\Users\jqbon\anaconda3\Lib\site-packages\jupyter_core\utils\__init__.py", line 165, in wrapped
    return loop.run_until_complete(inner)
           ^^^^^^^^^^^^^^^^^^^^^^^^^^^^^^
  File "C:\Users\jqbon\anaconda3\Lib\asyncio\base_events.py", line 687, in run_until_complete
    return future.result()
           ^^^^^^^^^^^^^^^
  File "C:\Users\jqbon\anaconda3\Lib\site-packages\nbclient\client.py", line 705, in async_execute
    await self.async_execute_cell(
  File "C:\Users\jqbon\anaconda3\Lib\site-packages\nbclient\client.py", line 1058, in async_execute_cell
    await self._check_raise_for_error(cell, cell_index, exec_reply)
  File "C:\Users\jqbon\anaconda3\Lib\site-packages\nbclient\client.py", line 914, in _check_raise_for_error
    raise CellExecutionError.from_cell_and_msg(cell, exec_reply_content)
nbclient.exceptions.CellExecutionError: An error occurred while executing the following cell:
------------------
#######################################################################
# Load data obtained in differential packed bed at steady state       #
#######################################################################

KDATA, HEADER = readdlm("SSKINETICS_Flow.csv", ',', Any, '\n', header = true)
KDATA = Float64.(KDATA)
CA  = KDATA[1:5, 1]
rCA = KDATA[1:5, 4]
CB  = KDATA[6:10, 2]
rCB = KDATA[6:10, 4]
T   = KDATA[11:15, 3]
rT  = KDATA[11:15, 4]
;


########################################################################
# Load same data in a data frame to pass into nicely formatted table   #
########################################################################

KDATAFRAME = load_object("SSKINETICS_Flow_df")
pretty_table(KDATAFRAME)

------------------


ArgumentError: Cannot open 'SSKINETICS_Flow.csv': not a file

Stacktrace:
 [1] readdlm_auto(input::String, dlm::Char, T::Type, eol::Char, auto::Bool; opts::@Kwargs{header::Bool})
   @ DelimitedFiles C:\Users\jqbon\.julia\packages\DelimitedFiles\aGcsu\src\DelimitedFiles.jl:234
 [2] readdlm_auto
   @ C:\Users\jqbon\.julia\packages\DelimitedFiles\aGcsu\src\DelimitedFiles.jl:233 [inlined]
 [3] #readdlm#6
   @ C:\Users\jqbon\.julia\packages\DelimitedFiles\aGcsu\src\DelimitedFiles.jl:226 [inlined]
 [4] top-level scope
   @ In[3]:5

